Workbook

Sheet Junho
A1: META JUNHO
A3: FATURAMENTO BRUTO
A5: Dia | C5: Meta | D5: Realizado | E5: Meta negativa | F5: Nova
A6: 1 | B6: segunda-feira | C6: 2441.7259 | E6: =C6*-1 -> -2441.7259 | F6: =C6-('Calculo '!$D$33*'Calculo '!B2) -> 2441.7259 | K6: Análises
A7: 2 | B7: terça-feira | C7: 2595.8213 | E7: =C7*-1 -> -2595.8212 | F7: =C7-('Calculo '!$D$33*'Calculo '!B3) -> 2595.8212 | L7: Acompanhamento meta diária
A8: 3 | B8: quarta-feira | C8: 3050.3745 | E8: =C8*-1 -> -3050.3745 | F8: =C8-('Calculo '!$D$33*'Calculo '!B4) -> 3050.3745 | L8: Meta Dia | M8: {=INDEX(F2:F36,MATCH(1,INDEX((D2:D36="")*(F2:F36<>""),0),0))} -> 2441.7259
A9: 4 | B9: quinta-feira | C9: 2625.0139 | E9: =C9*-1 -> -2625.0139 | F9: =C9-('Calculo '!$D$33*'Calculo '!B5) -> 2625.0139 | L9: Hora | M9: Meta | N9: Parciais | O9: Déficit
A10: 5 | B10: sexta-feira | C10: 2871.5239 | E10: =C10*-1 -> -2871.5239 | F10: =C10-('Calculo '!$D$33*'Calculo '!B6) -> 2871.5239 | L10: 0.45833333 | M10: =M8/COUNT(L10:L22) -> 203.47716 | O10: =M10-N10 -> 203.47716
A11: 6 | B11: sábado | C11: 4812.1842 | E11: =C11*-1 -> -4812.1842 | F11: =C11-('Calculo '!$D$33*'Calculo '!B7) -> 4812.1842 | G11: Meta semanal | H11: =SUM(C6:C12) -> 22914.253 | I11: =IF(H12>0,"Parabéns!!!","-") -> - | L11: 0.5 | M11: =M10*2 -> 406.95432 | O11: =M11-N11 -> 406.95432
A12: 7 | B12: domingo | C12: 4517.6093 | E12: =C12*-1 -> -4517.6093 | F12: =C12-('Calculo '!$D$33*'Calculo '!B8) -> 4517.6093 | G12: =IF(H12>0,"Superávit","Déficit") -> Déficit | H12: =SUM(D6:D12)-H11 -> -22914.253 | L12: 0.54166667 | M12: =M11+$M$10 -> 610.43148 | O12: =M12-N12 -> 610.43148
A13: 8 | B13: segunda-feira | C13: 2441.7259 | E13: =C13*-1 -> -2441.7259 | F13: =C13-('Calculo '!$D$33*'Calculo '!B9) -> 2441.7259 | L13: 0.58333333 | M13: =M12+$M$10 -> 813.90864 | O13: =M13-N13 -> 813.90864
A14: 9 | B14: terça-feira | C14: 2595.8213 | E14: =C14*-1 -> -2595.8212 | F14: =C14-('Calculo '!$D$33*'Calculo '!B10) -> 2595.8212 | L14: 0.625 | M14: =M13+$M$10 -> 1017.3858 | O14: =M14-N14 -> 1017.3858
A15: 10 | B15: quarta-feira | C15: 3050.3745 | E15: =C15*-1 -> -3050.3745 | F15: =C15-('Calculo '!$D$33*'Calculo '!B11) -> 3050.3745 | L15: 0.66666667 | M15: =M14+$M$10 -> 1220.863 | O15: =M15-N15 -> 1220.863
A16: 11 | B16: quinta-feira | C16: 2625.0139 | E16: =C16*-1 -> -2625.0139 | F16: =C16-('Calculo '!$D$33*'Calculo '!B12) -> 2625.0139 | L16: 0.70833333 | M16: =M15+$M$10 -> 1424.3401 | O16: =M16-N16 -> 1424.3401
A17: 12 | B17: sexta-feira | C17: 2871.5239 | E17: =C17*-1 -> -2871.5239 | F17: =C17-('Calculo '!$D$33*'Calculo '!B13) -> 2871.5239 | L17: 0.75 | M17: =M16+$M$10 -> 1627.8173 | O17: =M17-N17 -> 1627.8173
A18: 13 | B18: sábado | C18: 4812.1842 | E18: =C18*-1 -> -4812.1842 | F18: =C18-('Calculo '!$D$33*'Calculo '!B14) -> 4812.1842 | L18: 0.79166667 | M18: =M17+$M$10 -> 1831.2944 | O18: =M18-N18 -> 1831.2944
A19: 14 | B19: domingo | C19: 4517.6093 | E19: =C19*-1 -> -4517.6093 | F19: =C19-('Calculo '!$D$33*'Calculo '!B15) -> 4517.6093 | G19: Meta semanal | H19: =SUM(C13:C20) -> 25355.979 | I19: =IF(H20>0,"Parabéns!!!","-") -> - | L19: 0.83333333 | M19: =M18+$M$10 -> 2034.7716 | O19: =M19-N19 -> 2034.7716
A20: 15 | B20: segunda-feira | C20: 2441.7259 | E20: =C20*-1 -> -2441.7259 | F20: =C20-('Calculo '!$D$33*'Calculo '!B16) -> 2441.7259 | G20: =IF(H20>0,"Superávit","Déficit") -> Déficit | H20: =SUM(D13:D20)-H19 -> -25355.979 | L20: 0.875 | M20: =M19+$M$10 -> 2238.2488 | O20: =M20-N20 -> 2238.2488
A21: 16 | B21: terça-feira | C21: 2595.8213 | E21: =C21*-1 -> -2595.8212 | F21: =C21-('Calculo '!$D$33*'Calculo '!B17) -> 2595.8212 | L21: 0.91666667 | M21: =M20+$M$10 -> 2441.7259 | O21: =M21-N21 -> 2441.7259
A22: 17 | B22: quarta-feira | C22: 3050.3745 | E22: =C22*-1 -> -3050.3745 | F22: =C22-('Calculo '!$D$33*'Calculo '!B18) -> 3050.3745
A23: 18 | B23: quinta-feira | C23: 2625.0139 | E23: =C23*-1 -> -2625.0139 | F23: =C23-('Calculo '!$D$33*'Calculo '!B19) -> 2625.0139
A24: 19 | B24: sexta-feira | C24: 2871.5239 | E24: =C24*-1 -> -2871.5239 | F24: =C24-('Calculo '!$D$33*'Calculo '!B20) -> 2871.5239
A25: 20 | B25: sábado | C25: 4812.1842 | E25: =C25*-1 -> -4812.1842 | F25: =C25-('Calculo '!$D$33*'Calculo '!B21) -> 4812.1842
A26: 21 | B26: domingo | C26: 4517.6093 | E26: =C26*-1 -> -4517.6093 | F26: =C26-('Calculo '!$D$33*'Calculo '!B22) -> 4517.6093
A27: 22 | B27: segunda-feira | C27: 2441.7259 | E27: =C27*-1 -> -2441.7259 | F27: =C27-('Calculo '!$D$33*'Calculo '!B23) -> 2441.7259 | G27: Meta semanal | H27: =SUM(C21:C28) -> 25510.074 | I27: =IF(H28>0,"Parabéns!!!","-") -> -
A28: 23 | B28: terça-feira | C28: 2595.8213 | E28: =C28*-1 -> -2595.8212 | F28: =C28-('Calculo '!$D$33*'Calculo '!B24) -> 2595.8212 | G28: =IF(H28>0,"Superávit","Déficit") -> Déficit | H28: =SUM(D21:D28)-H27 -> -25510.074
A29: 24 | B29: quarta-feira | C29: 3050.3745 | E29: =C29*-1 -> -3050.3745 | F29: =C29-('Calculo '!$D$33*'Calculo '!B25) -> 3050.3745
A30: 25 | B30: quinta-feira | C30: 2625.0139 | E30: =C30*-1 -> -2625.0139 | F30: =C30-('Calculo '!$D$33*'Calculo '!B26) -> 2625.0139
A31: 26 | B31: sexta-feira | C31: 2871.5239 | E31: =C31*-1 -> -2871.5239 | F31: =C31-('Calculo '!$D$33*'Calculo '!B27) -> 2871.5239
A32: 27 | B32: sábado | C32: 4812.1842 | E32: =C32*-1 -> -4812.1842 | F32: =C32-('Calculo '!$D$33*'Calculo '!B28) -> 4812.1842
A33: 28 | B33: domingo | C33: 4517.6093 | E33: =C33*-1 -> -4517.6093 | F33: =C33-('Calculo '!$D$33*'Calculo '!B29) -> 4517.6093
A34: 29 | B34: segunda-feira | C34: 2441.7259 | F34: =C34-('Calculo '!$D$33*'Calculo '!B30) -> 2441.7259 | G34: Meta semanal | H34: =SUM(C29:C35) -> 22914.253 | I34: =IF(H28>0,"Parabéns!!!","-") -> -
A35: 30 | B35: terça-feira | C35: 2595.8213 | F35: =C35-('Calculo '!$D$33*'Calculo '!B31) -> 2595.8212 | G35: =IF(H35>0,"Superávit","Déficit") -> Déficit | H35: =SUM(D29:D35)-H34 -> -22914.253
A37: Total | C37: =SUM(C6:C36) -> 96694.559 | D37: =SUM(D6:D36) -> 0
A38: =IF(D38>0,"Superávit","Déficit") -> Déficit | D38: =D37-B56 -> 0
F39: =F40+D37 -> 0
D40: =D37/24 -> 0 | F40: =D40*6 -> 0
B56: =SUMIF(D6:D36,"<>",C6:C36) -> 0

Sheet backup
A1: META JUNHO
A3: FATURAMENTO BRUTO
A5: Dia | C5: Meta | D5: Realizado | E5: Meta negativa | F5: Nova
A6: 1 | B6: segunda-feira | C6: 2441.7259 | E6: =C6*-1 -> -2441.7259 | F6: =C6-('Calculo '!$D$33*'Calculo '!B2) -> 2441.7259 | K6: Análises
A7: 2 | B7: terça-feira | C7: 2595.8213 | E7: =C7*-1 -> -2595.8212 | F7: =C7-('Calculo '!$D$33*'Calculo '!B3) -> 2595.8212 | L7: Acompanhamento meta diária
A8: 3 | B8: quarta-feira | C8: 3050.3745 | E8: =C8*-1 -> -3050.3745 | F8: =C8-('Calculo '!$D$33*'Calculo '!B4) -> 3050.3745 | L8: Meta Dia | M8: {=INDEX(F2:F36,MATCH(1,INDEX((D2:D36="")*(F2:F36<>""),0),0))} -> 2441.7259
A9: 4 | B9: quinta-feira | C9: 2625.0139 | E9: =C9*-1 -> -2625.0139 | F9: =C9-('Calculo '!$D$33*'Calculo '!B5) -> 2625.0139 | L9: Hora | M9: Meta | N9: Parciais | O9: Déficit
A10: 5 | B10: sexta-feira | C10: 2871.5239 | E10: =C10*-1 -> -2871.5239 | F10: =C10-('Calculo '!$D$33*'Calculo '!B6) -> 2871.5239 | L10: 0.45833333 | M10: =M8/COUNT(L10:L22) -> 203.47716 | O10: =M10-N10 -> 203.47716
A11: 6 | B11: sábado | C11: 4812.1842 | E11: =C11*-1 -> -4812.1842 | F11: =C11-('Calculo '!$D$33*'Calculo '!B7) -> 4812.1842 | G11: Meta semanal | H11: =SUM(C6:C12) -> 22914.253 | I11: =IF(H12>0,"Parabéns!!!","-") -> - | L11: 0.5 | M11: =M10*2 -> 406.95432 | O11: =M11-N11 -> 406.95432
A12: 7 | B12: domingo | C12: 4517.6093 | E12: =C12*-1 -> -4517.6093 | F12: =C12-('Calculo '!$D$33*'Calculo '!B8) -> 4517.6093 | G12: =IF(H12>0,"Superávit","Déficit") -> Déficit | H12: =SUM(D6:D12)-H11 -> -22914.253 | L12: 0.54166667 | M12: =M11+$M$10 -> 610.43148 | O12: =M12-N12 -> 610.43148
A13: 8 | B13: segunda-feira | C13: 2441.7259 | E13: =C13*-1 -> -2441.7259 | F13: =C13-('Calculo '!$D$33*'Calculo '!B9) -> 2441.7259 | L13: 0.58333333 | M13: =M12+$M$10 -> 813.90864 | O13: =M13-N13 -> 813.90864
A14: 9 | B14: terça-feira | C14: 2595.8213 | E14: =C14*-1 -> -2595.8212 | F14: =C14-('Calculo '!$D$33*'Calculo '!B10) -> 2595.8212 | L14: 0.625 | M14: =M13+$M$10 -> 1017.3858 | O14: =M14-N14 -> 1017.3858
A15: 10 | B15: quarta-feira | C15: 3050.3745 | E15: =C15*-1 -> -3050.3745 | F15: =C15-('Calculo '!$D$33*'Calculo '!B11) -> 3050.3745 | L15: 0.66666667 | M15: =M14+$M$10 -> 1220.863 | O15: =M15-N15 -> 1220.863
A16: 11 | B16: quinta-feira | C16: 2625.0139 | E16: =C16*-1 -> -2625.0139 | F16: =C16-('Calculo '!$D$33*'Calculo '!B12) -> 2625.0139 | L16: 0.70833333 | M16: =M15+$M$10 -> 1424.3401 | O16: =M16-N16 -> 1424.3401
A17: 12 | B17: sexta-feira | C17: 2871.5239 | E17: =C17*-1 -> -2871.5239 | F17: =C17-('Calculo '!$D$33*'Calculo '!B13) -> 2871.5239 | L17: 0.75 | M17: =M16+$M$10 -> 1627.8173 | O17: =M17-N17 -> 1627.8173
A18: 13 | B18: sábado | C18: 4812.1842 | E18: =C18*-1 -> -4812.1842 | F18: =C18-('Calculo '!$D$33*'Calculo '!B14) -> 4812.1842 | L18: 0.79166667 | M18: =M17+$M$10 -> 1831.2944 | O18: =M18-N18 -> 1831.2944
A19: 14 | B19: domingo | C19: 4517.6093 | E19: =C19*-1 -> -4517.6093 | F19: =C19-('Calculo '!$D$33*'Calculo '!B15) -> 4517.6093 | G19: Meta semanal | H19: =SUM(C13:C20) -> 25355.979 | I19: =IF(H20>0,"Parabéns!!!","-") -> - | L19: 0.83333333 | M19: =M18+$M$10 -> 2034.7716 | O19: =M19-N19 -> 2034.7716
A20: 15 | B20: segunda-feira | C20: 2441.7259 | E20: =C20*-1 -> -2441.7259 | F20: =C20-('Calculo '!$D$33*'Calculo '!B16) -> 2441.7259 | G20: =IF(H20>0,"Superávit","Déficit") -> Déficit | H20: =SUM(D13:D20)-H19 -> -25355.979 | L20: 0.875 | M20: =M19+$M$10 -> 2238.2488 | O20: =M20-N20 -> 2238.2488
A21: 16 | B21: terça-feira | C21: 2595.8213 | E21: =C21*-1 -> -2595.8212 | F21: =C21-('Calculo '!$D$33*'Calculo '!B17) -> 2595.8212 | L21: 0.91666667 | M21: =M20+$M$10 -> 2441.7259 | O21: =M21-N21 -> 2441.7259
A22: 17 | B22: quarta-feira | C22: 3050.3745 | E22: =C22*-1 -> -3050.3745 | F22: =C22-('Calculo '!$D$33*'Calculo '!B18) -> 3050.3745
A23: 18 | B23: quinta-feira | C23: 2625.0139 | E23: =C23*-1 -> -2625.0139 | F23: =C23-('Calculo '!$D$33*'Calculo '!B19) -> 2625.0139
A24: 19 | B24: sexta-feira | C24: 2871.5239 | E24: =C24*-1 -> -2871.5239 | F24: =C24-('Calculo '!$D$33*'Calculo '!B20) -> 2871.5239
A25: 20 | B25: sábado | C25: 4812.1842 | E25: =C25*-1 -> -4812.1842 | F25: =C25-('Calculo '!$D$33*'Calculo '!B21) -> 4812.1842
A26: 21 | B26: domingo | C26: 4517.6093 | E26: =C26*-1 -> -4517.6093 | F26: =C26-('Calculo '!$D$33*'Calculo '!B22) -> 4517.6093
A27: 22 | B27: segunda-feira | C27: 2441.7259 | E27: =C27*-1 -> -2441.7259 | F27: =C27-('Calculo '!$D$33*'Calculo '!B23) -> 2441.7259 | G27: Meta semanal | H27: =SUM(C21:C28) -> 25510.074 | I27: =IF(H28>0,"Parabéns!!!","-") -> -
A28: 23 | B28: terça-feira | C28: 2595.8213 | E28: =C28*-1 -> -2595.8212 | F28: =C28-('Calculo '!$D$33*'Calculo '!B24) -> 2595.8212 | G28: =IF(H28>0,"Superávit","Déficit") -> Déficit | H28: =SUM(D21:D28)-H27 -> -25510.074
A29: 24 | B29: quarta-feira | C29: 3050.3745 | E29: =C29*-1 -> -3050.3745 | F29: =C29-('Calculo '!$D$33*'Calculo '!B25) -> 3050.3745
A30: 25 | B30: quinta-feira | C30: 2625.0139 | E30: =C30*-1 -> -2625.0139 | F30: =C30-('Calculo '!$D$33*'Calculo '!B26) -> 2625.0139
A31: 26 | B31: sexta-feira | C31: 2871.5239 | E31: =C31*-1 -> -2871.5239 | F31: =C31-('Calculo '!$D$33*'Calculo '!B27) -> 2871.5239
A32: 27 | B32: sábado | C32: 4812.1842 | E32: =C32*-1 -> -4812.1842 | F32: =C32-('Calculo '!$D$33*'Calculo '!B28) -> 4812.1842
A33: 28 | B33: domingo | C33: 4517.6093 | E33: =C33*-1 -> -4517.6093 | F33: =C33-('Calculo '!$D$33*'Calculo '!B29) -> 4517.6093
A34: 29 | B34: segunda-feira | C34: 2441.7259 | F34: =C34-('Calculo '!$D$33*'Calculo '!B30) -> 2441.7259 | G34: Meta semanal | H34: =SUM(C29:C35) -> 22914.253 | I34: =IF(H28>0,"Parabéns!!!","-") -> -
A35: 30 | B35: terça-feira | C35: 2595.8213 | F35: =C35-('Calculo '!$D$33*'Calculo '!B31) -> 2595.8212 | G35: =IF(H35>0,"Superávit","Déficit") -> Déficit | H35: =SUM(D29:D35)-H34 -> -22914.253
A37: Total | C37: =SUM(C6:C36) -> 96694.559 | D37: =SUM(D6:D36) -> 0
A38: =IF(D38>0,"Superávit","Déficit") -> Déficit | D38: =D37-B56 -> 0
B56: =SUMIF(D6:D36,"<>",C6:C36) -> 0

Sheet Calculo 
B1: Porcentagem | C1: Valor Porcentagem | D1: Diferença
A2: 1 | B2: =Junho!C6/'Calculo '!C2 -> 0.025251947 | C2: =Junho!$C$37-Junho!$D$37+E2 -> 96694.559 | D2: =SUMIF(Junho!C6:D6,"<>",Junho!D6:E6) -> 0 | E2: =SUM(D2) -> 0
A3: 2 | B3: =Junho!C7/'Calculo '!C3 -> 0.026845577 | C3: =Junho!$C$37-Junho!$D$37+E3 -> 96694.559 | D3: =SUMIF(Junho!C7:D7,"<>",Junho!D7:E7) -> 0 | E3: =SUM($D$2:D3) -> 0
A4: 3 | B4: =Junho!C8/'Calculo '!C4 -> 0.031546496 | C4: =Junho!$C$37-Junho!$D$37+E4 -> 96694.559 | D4: =SUMIF(Junho!C8:D8,"<>",Junho!D8:E8) -> 0 | E4: =SUM($D$2:D4) -> 0
A5: 4 | B5: =Junho!C9/'Calculo '!C5 -> 0.027147483 | C5: =Junho!$C$37-Junho!$D$37+E5 -> 96694.559 | D5: =SUMIF(Junho!C9:D9,"<>",Junho!D9:E9) -> 0 | E5: =SUM($D$2:D5) -> 0
A6: 5 | B6: =Junho!C10/'Calculo '!C6 -> 0.029696851 | C6: =Junho!$C$37-Junho!$D$37+E6 -> 96694.559 | D6: =SUMIF(Junho!C10:D10,"<>",Junho!D10:E10) -> 0 | E6: =SUM($D$2:D6) -> 0
A7: 6 | B7: =Junho!C11/'Calculo '!C7 -> 0.049766856 | C7: =Junho!$C$37-Junho!$D$37+E7 -> 96694.559 | D7: =SUMIF(Junho!C11:D11,"<>",Junho!D11:E11) -> 0 | E7: =SUM($D$2:D7) -> 0
A8: 7 | B8: =Junho!C12/'Calculo '!C8 -> 0.046720408 | C8: =Junho!$C$37-Junho!$D$37+E8 -> 96694.559 | D8: =SUMIF(Junho!C12:D12,"<>",Junho!D12:E12) -> 0 | E8: =SUM($D$2:D8) -> 0
A9: 8 | B9: =Junho!C13/'Calculo '!C9 -> 0.025251947 | C9: =Junho!$C$37-Junho!$D$37+E9 -> 96694.559 | D9: =SUMIF(Junho!C13:D13,"<>",Junho!D13:E13) -> 0 | E9: =SUM($D$2:D9) -> 0
A10: 9 | B10: =Junho!C14/'Calculo '!C10 -> 0.026845577 | C10: =Junho!$C$37-Junho!$D$37+E10 -> 96694.559 | D10: =SUMIF(Junho!C14:D14,"<>",Junho!D14:E14) -> 0 | E10: =SUM($D$2:D10) -> 0
A11: 10 | B11: =Junho!C15/'Calculo '!C11 -> 0.031546496 | C11: =Junho!$C$37-Junho!$D$37+E11 -> 96694.559 | D11: =SUMIF(Junho!C15:D15,"<>",Junho!D15:E15) -> 0 | E11: =SUM($D$2:D11) -> 0
A12: 11 | B12: =Junho!C16/'Calculo '!C12 -> 0.027147483 | C12: =Junho!$C$37-Junho!$D$37+E12 -> 96694.559 | D12: =SUMIF(Junho!C16:D16,"<>",Junho!D16:E16) -> 0 | E12: =SUM($D$2:D12) -> 0
A13: 12 | B13: =Junho!C17/'Calculo '!C13 -> 0.029696851 | C13: =Junho!$C$37-Junho!$D$37+E13 -> 96694.559 | D13: =SUMIF(Junho!C17:D17,"<>",Junho!D17:E17) -> 0 | E13: =SUM($D$2:D13) -> 0
A14: 13 | B14: =Junho!C18/'Calculo '!C14 -> 0.049766856 | C14: =Junho!$C$37-Junho!$D$37+E14 -> 96694.559 | D14: =SUMIF(Junho!C18:D18,"<>",Junho!D18:E18) -> 0 | E14: =SUM($D$2:D14) -> 0
... A32: 31 | B32: =Junho!C36/'Calculo '!C32 -> 0 | C32: =Junho!$C$37-Junho!$D$37+E32 -> 96694.559 | D32: =SUMIF(Junho!C36:D36,"<>",Junho!D36:E36) -> 0 | E32: =SUM($D$2:D32) -> 0
D33: =SUM(D2:D32) -> 0

Sheet Calculo mensal
A2: Dia da Semana | B2: Fevereiro | C2: Março | D2: Abril | E2: Maio | F2: junho | G2: julho | H2: agosto | I2: setembro | J2: outubro | K2: novembro | L2: Dezembro | M2: Janeiro | N2: Fevereiro | O2: Março | P2: Abril | Q2: Maio | R2: Junho | S2: Julho | T2: Agosto | U2: Setembro | V2: Outubro | W2: Novembro | X2: Dezembro | Y2: Janeiro | Z2: Fevereiro | AA2: Março | AB2: Abril | AC2: Maio | AD2: Junho | AE2: Julho | AF2: Agosto | AG2: Setembro | AH2: Outubro | AI2: Novembro | AJ2: Dezembro | AK2: Janeiro | AL2: Fevereiro | AM2: Março | AN2: Abril | AO2: Maio
A3: segunda-feira | M3: 4329 | P3: 2397.07 | S3: 2267.5 | AG3: 3205.01 | AJ3: 3679
A4: terça-feira | H4: 4263 | M4: 3538.5 | P4: 3490.12 | S4: 3462.5 | V4: 2892.04 | AB4: 2152.27 | AE4: 1645.71 | AG4: 2619 | AJ4: 2380
A5: quarta-feira | B5: 3910.81 | C5: 2935 | H5: 3839.5 | K5: 3877.5 | M5: 3345.5 | P5: 2457.5 | Q5: 3035.03 | S5: 3879.05 | V5: 3157.5 | AB5: 2586.75 | AE5: 2767.5 | AG5: 2668.51 | AH5: 1866.01 | AJ5: 3015.02 | AN5: 1454
A6: quinta-feira | B6: 2479.32 | C6: 2988 | E6: 3650 | F6: 2119 | H6: 4248.04 | K6: 6601.53 | M6: 2988.51 | N6: 4371.62 | P6: 4090.51 | Q6: 2139.02 | S6: 3291 | T6: 2321.08 | V6: 2555.52 | Y6: 2801.25 | AB6: 1924.01 | AC6: 4156.01 | AE6: 2230.26 | AG6: 2248.51 | AH6: 3476.5 | AJ6: 3900.5 | AK6: 2674 | AN6: 1926.5
A7: sexta-feira | B7: 4701.23 | C7: 3214 | E7: 2156 | F7: 2262 | H7: 4161.51 | I7: 2905.5 | K7: 3818.04 | L7: 4192.5 | M7: 3696 | N7: 4086.52 | O7: 5660.52 | P7: 3500.52 | Q7: 1931.02 | S7: 2809.01 | T7: 2473.12 | V7: 6734.42 | W7: 2717.01 | Y7: 2801.51 | AB7: 2322.27 | AC7: 3059.75 | AE7: 3552.76 | AF7: 1669 | AG7: 1568 | AH7: 5068.51 | AJ7: 2976.01 | AK7: 4655.5 | AN7: 2649 | AO7: 6527.5
A8: sábado | B8: 6723.1 | C8: 4675.5 | D8: 4355 | E8: 2190 | F8: 4739.5 | G8: 3232.5 | H8: 6064 | I8: 5756 | K8: 2671 | L8: 5839.52 | M8: 5441.55 | N8: 8196.01 | O8: 7785.52 | P8: 5998.03 | Q8: 2095.53 | R8: 2436.04 | S8: 3387.03 | T8: 2189.54 | V8: 7501.06 | W8: 3755.01 | Y8: 4097.75 | Z8: 5627.25 | AA8: 4655 | AB8: 2719.76 | AC8: 3847.75 | AE8: 2805 | AF8: 3284.15 | AG8: 3452.51 | AH8: 5921.51 | AI8: 4149.5 | AJ8: 4037.5 | AK8: 5409.5 | AN8: 4476.5 | AO8: 3245.5
A9: domingo | B9: 5052.11 | C9: 5030 | D9: 4468.5 | E9: 2986 | F9: 3980.5 | G9: 3942.5 | H9: 4671.02 | I9: 4584.01 | J9: 7505 | K9: 4268.02 | L9: 4675.5 | M9: 4982 | N9: 6234.5 | O9: 7755.51 | P9: 4436.54 | Q9: 3064.05 | R9: 1830 | S9: 3640 | T9: 2452.03 | U9: 2102 | V9: 5339.56 | W9: 2770.5 | X9: 3470.75 | Y9: 3457.81 | Z9: 4641.26 | AA9: 3510.53 | AB9: 3215.25 | AC9: 3424.27 | AD9: 4180.83 | AE9: 3583.24 | AF9: 3413.9 | AG9: 3052.5 | AH9: 6536.4 | AI9: 3339.9 | AJ9: 3251.01 | AK9: 5360.01 | AL9: 6048.5 | AM9: 3500.5 | AN9: 2620.5 | AO9: 6348
A10: segunda-feira | B10: 1924.1 | C10: 1963.5 | D10: 2511 | E10: 2641.5 | F10: 2131.5 | G10: 2610.5 | H10: 2794.5 | I10: 2163.51 | J10: 4109.51 | K10: 1906 | L10: 3183.53 | M10: 2145.5 | N10: 3300.63 | O10: 3477.02 | P10: 2049 | Q10: 1989.07 | R10: 2002.58 | S10: 3263.04 | T10: 2502.51 | U10: 2738.03 | V10: 4573.11 | W10: 2204.51 | X10: 3672.88 | Y10: 2484 | Z10: 2798.26 | AA10: 4028.76 | AB10: 2848.51 | AC10: 2122.81 | AD10: 1793 | AE10: 3226 | AF10: 3270 | AG10: 2873.5 | AH10: 4037.02 | AI10: 2232 | AJ10: 2690.5 | AK10: 2465 | AL10: 2024.5 | AM10: 1674.5 | AN10: 1649.01 | AO10: 2540
A11: terça-feira | B11: 2705.14 | C11: 2828.5 | D11: 2393.5 | E11: 4765 | F11: 1955.5 | G11: 2460 | H11: 3748.51 | I11: 5262.5 | J11: 4020 | K11: 3034.5 | L11: 2779 | M11: 2845 | N11: 4051.51 | O11: 4959.07 | P11: 3501.51 | Q11: 2624.08 | R11: 2648.57 | S11: 2942.51 | T11: 2849.68 | U11: 2823.51 | V11: 4419.53 | W11: 3185.51 | X11: 3349.51 | Y11: 3829.85 | Z11: 3123.29 | AA11: 3807.25 | AB11: 1988.75 | AC11: 2852.76 | AD11: 1909.01 | AE11: 1465.51 | AF11: 2543.54 | AG11: 1530.5 | AH11: 5475.01 | AI11: 1153.25 | AJ11: 3328.5 | AK11: 2457.51 | AL11: 2597.5 | AM11: 3251 | AN11: 1514 | AO11: 1781
A12: quarta-feira | B12: 2399.9 | C12: 3716 | D12: 2022.5 | E12: 4180.5 | F12: 3011.5 | G12: 2996.5 | H12: 3880.5 | I12: 2961.01 | J12: 3080.5 | K12: 3194.02 | L12: 2817.5 | M12: 3176.51 | N12: 3850 | O12: 4626.51 | P12: 3855.04 | Q12: 2410.55 | R12: 2459.08 | S12: 2437.05 | T12: 1872.57 | U12: 2639.54 | V12: 4276.57 | W12: 2361.06 | X12: 2933 | Y12: 4595.25 | Z12: 3196.5 | AA12: 3865.78 | AB12: 2392 | AC12: 2315.5 | AD12: 2132.76 | AE12: 2495.5 | AF12: 2101.01 | AG12: 2097.29 | AH12: 7205.5 | AI12: 2083.5 | AJ12: 2934.01 | AK12: 3659 | AL12: 2935.91 | AM12: 2356 | AN12: 2793 | AO12: 3419.5
A13: quinta-feira | B13: 3475.38 | C13: 2288.5 | D13: 2776 | E13: 1962 | F13: 4296 | G13: 2261.52 | H13: 2187.51 | I13: 4629 | J13: 2868.01 | K13: 3569.03 | L13: 3965.53 | M13: 3624.04 | N13: 2967.53 | O13: 4090.51 | P13: 4783.54 | Q13: 2216.54 | R13: 1952.52 | S13: 3111.5 | T13: 3432.62 | U13: 1626.01 | V13: 4676.55 | W13: 5680.52 | X13: 2908 | Y13: 3879.5 | Z13: 4774.27 | AA13: 4310.26 | AB13: 2441.01 | AC13: 2369.26 | AD13: 1690.26 | AE13: 3523.02 | AF13: 2547.42 | AG13: 2250 | AH13: 7879.81 | AI13: 3006.26 | AJ13: 2524 | AK13: 2701.5 | AL13: 3079.5 | AM13: 1897.5 | AN13: 2022.5 | AO13: 3043.5
A14: sexta-feira | B14: 4031.92 | C14: 3160.5 | D14: 4051.5 | E14: 2081.5 | F14: 3098.5 | G14: 2952.01 | H14: 2958 | I14: 3444 | J14: 3473.51 | K14: 3728.02 | L14: 3688 | M14: 3733.53 | N14: 3114.53 | O14: 6856.5 | P14: 3759.54 | Q14: 2109.57 | R14: 2451.6 | S14: 2512.56 | T14: 2343.63 | U14: 2656.51 | V14: 4732.57 | W14: 6553.12 | X14: 2907.85 | Y14: 2982.75 | Z14: 5214.75 | AA14: 4051.5 | AB14: 3065.81 | AC14: 2985.26 | AD14: 2939.29 | AE14: 3388.5 | AF14: 1932.5 | AG14: 2097.93 | AH14: 6661.76 | AI14: 3303.75 | AJ14: 2651 | AK14: 3397.5 | AL14: 2657.5 | AM14: 2130.5 | AN14: 2358 | AO14: 1952
A15: sábado | B15: 5536.05 | C15: 5589.5 | D15: 5664.5 | E15: 2482 | F15: 3258.5 | G15: 2952.01 | H15: 4542.01 | I15: 4754.01 | J15: 6836 | K15: 4232 | L15: 5054.5 | M15: 5902.04 | N15: 4429.56 | O15: 7348.01 | P15: 5133.04 | Q15: 2295.52 | R15: 2090 | S15: 3434.54 | T15: 3024.06 | U15: 3874 | V15: 5725.01 | W15: 8614 | X15: 3392.75 | Y15: 5174 | Z15: 6359.77 | AA15: 6328.75 | AB15: 3065.25 | AC15: 3706.01 | AD15: 3811.75 | AE15: 4008.16 | AF15: 3584.42 | AG15: 3593.8 | AH15: 8622 | AI15: 5357.5 | AJ15: 4429.01 | AK15: 5844.01 | AL15: 5130 | AM15: 3652.01 | AN15: 4750.5 | AO15: 6028.06
A16: domingo | B16: 5480.5 | C16: 4383 | D16: 3716 | E16: 2258 | F16: 3123.5 | G16: 4798.5 | H16: 3816.5 | I16: 3477.13 | J16: 4521 | K16: 6334.5 | L16: 6274 | M16: 6163.5 | N16: 5069.52 | O16: 7547.04 | P16: 4879.5 | Q16: 2134.07 | R16: 1864.57 | S16: 2638.06 | T16: 1972.08 | U16: 2695.5 | V16: 6097.03 | W16: 8551.27 | X16: 2658.25 | Y16: 3844.25 | Z16: 7420.75 | AA16: 5694.01 | AB16: 2786.01 | AC16: 2910.75 | AD16: 4635.29 | AE16: 2679.07 | AF16: 3536.91 | AG16: 2751 | AH16: 7934.7 | AI16: 5717.4 | AJ16: 2350.5 | AK16: 5247 | AL16: 7023.5 | AM16: 3740.5 | AN16: 4090 | AO16: 3823
A17: segunda-feira | B17: 4060.5 | C17: 1733 | D17: 2381.5 | E17: 3488 | F17: 2140.5 | G17: 2475 | H17: 4478 | I17: 2128.01 | J17: 1880.5 | K17: 2463.52 | L17: 3076 | M17: 2846.51 | N17: 3647.55 | O17: 3917.53 | P17: 3081.04 | Q17: 3067.68 | R17: 2220.52 | S17: 2651.58 | T17: 2737.7 | U17: 2681.05 | V17: 1874.51 | W17: 4360.75 | X17: 2929.75 | Y17: 2271.75 | Z17: 4290.77 | AA17: 2149.75 | AB17: 2065.51 | AC17: 1417.26 | AD17: 2079.5 | AE17: 1470.52 | AF17: 2170.52 | AG17: 2154.75 | AH17: 1076.01 | AI17: 2552 | AJ17: 1849 | AK17: 2547.5 | AL17: 3695 | AM17: 2013.5 | AN17: 1953 | AO17: 1685
A18: terça-feira | B18: 3627.5 | C18: 3690 | D18: 1988 | E18: 3590.5 | F18: 2227.5 | G18: 3082.52 | H18: 3859 | I18: 2463 | J18: 2136.59 | K18: 3122.5 | L18: 3028.01 | M18: 3897.01 | N18: 4739.5 | O18: 5202 | P18: 3665.53 | Q18: 2663.59 | R18: 1779.11 | S18: 2505.5 | T18: 2837.1 | U18: 2430.52 | V18: 3094.03 | W18: 5184.8 | X18: 2934.75 | Y18: 3730.25 | Z18: 4036 | AA18: 2203.75 | AB18: 1480.76 | AC18: 1942.27 | AD18: 2123.76 | AE18: 2484.4 | AF18: 3052 | AG18: 1894.51 | AH18: 2593.01 | AI18: 3252.5 | AJ18: 1986.51 | AK18: 1989 | AL18: 3054.5 | AM18: 2396 | AN18: 2354.55 | AO18: 2066
A19: quarta-feira | B19: 3655.62 | C19: 3608.5 | D19: 2640 | E19: 2005.5 | F19: 3156.51 | G19: 3377.5 | H19: 3860.01 | I19: 3068 | J19: 3153.51 | K19: 8558.5 | L19: 3176 | M19: 3552.02 | N19: 3983.03 | O19: 4511.03 | P19: 3542.58 | Q19: 2751.06 | R19: 3044.03 | S19: 3621.52 | T19: 3064.52 | U19: 2415.5 | V19: 2191.5 | W19: 6840.76 | X19: 2933.75 | Y19: 3770.26 | Z19: 5012.26 | AA19: 3651 | AB19: 3039 | AC19: 2700 | AD19: 2997.75 | AE19: 2447.5 | AF19: 3561.52 | AG19: 2338.51 | AH19: 2003.52 | AI19: 1830.5 | AJ19: 1610 | AK19: 3473.04 | AL19: 4457 | AM19: 5202 | AN19: 2607.51 | AO19: 3548
A20: quinta-feira | B20: 2025 | C20: 2119.5 | D20: 2426.5 | E20: 2120.5 | F20: 2657.51 | G20: 3606.02 | H20: 2902.5 | I20: 2362 | J20: 6548.5 | K20: 2608.5 | L20: 3841.51 | M20: 2445.5 | N20: 4318.03 | O20: 2940.52 | P20: 3078.1 | Q20: 2984.53 | R20: 2266.57 | S20: 2359.5 | T20: 2748.05 | U20: 2605.52 | V20: 2777.54 | W20: 3973.78 | X20: 2501.6 | Y20: 3424.02 | Z20: 4701.75 | AA20: 3370.25 | AB20: 2141.04 | AC20: 2343 | AD20: 3996.29 | AE20: 2762.5 | AF20: 2677.52 | AG20: 1838 | AH20: 2930.52 | AI20: 2209 | AJ20: 2127.5 | AK20: 2970 | AL20: 1257 | AM20: 2442.5 | AN20: 1818.5 | AO20: 1981.53
... A32: terça-feira | B32: 4354 | C32: 2440.5 | D32: 2390 | E32: 4254.5 | F32: 3506 | G32: 6342.01 | H32: 2423.5 | I32: 3361.5 | J32: 2282 | K32: 2935.53 | L32: 3151.51 | M32: 3881.01 | N32: 6711.53 | O32: 3560.5 | P32: 3683.05 | Q32: 3429.01 | R32: 3827.66 | S32: 3831.03 | T32: 3321.55 | U32: 2304.51 | V32: 2468.53 | W32: 2917.27 | X32: 0 | Y32: 4182 | Z32: 3972.76 | AA32: 2303.25 | AB32: 2110.78 | AC32: 2284.83 | AD32: 1397.52 | AE32: 2105.26 | AF32: 2295 | AG32: 2125.52 | AH32: 835 | AI32: 1636 | AJ32: 2334.51 | AK32: 2564 | AL32: 2723.5 | AM32: 2301 | AN32: 2608.52 | AO32: 1590.5
A33: quarta-feira | C33: 2898.31 | D33: 2691 | E33: 2231 | F33: 3397 | G33: 5435 | H33: 3032.01 | I33: 3391 | J33: 2955 | K33: 2625 | L33: 3852.5 | M33: 3380 | N33: 7669.51 | O33: 3606.51 | Q33: 2695.66 | R33: 3091.06 | S33: 2610.6 | T33: 2664.13 | U33: 2470.5 | V33: 2949 | W33: 3455.25 | X33: 1349.75 | Y33: 4014.01 | Z33: 3786.25 | AA33: 3328.25 | AB33: 3014.75 | AC33: 2608.02 | AD33: 2021.76 | AE33: 2285.01 | AF33: 3937.5 | AH33: 2232.03 | AI33: 2386 | AJ33: 0 | AK33: 4048.5 | AL33: 2723.5 | AM33: 2330.5 | AN33: 3424.5 | AO33: 3014.5
A34: quinta-feira | C34: 3012 | D34: 2403.5 | E34: 2854.5 | F34: 2585.51 | G34: 4686 | H34: 4048.52 | I34: 2520.05 | J34: 2615 | K34: 3455 | L34: 4043 | N34: 4429.56 | O34: 3487.53 | Q34: 2140.55 | R34: 3403.54 | T34: 3207.61 | U34: 2039.5 | V34: 3705.03 | W34: 5585.51 | X34: 2033.5 | Y34: 3410.67 | Z34: 2676.76 | AA34: 3336.29 | AC34: 1925.53 | AD34: 1648.5 | AE34: 2123.8 | AF34: 2547 | AH34: 1986 | AI34: 3025.52 | AK34: 3109 | AL34: 2439.5 | AM34: 1821.5 | AN34: 2596.5 | AO34: 2225
A35: sexta-feira | C35: 7191.5 | D35: 3068 | E35: 3672 | F35: 2997.01 | G35: 4838.01 | I35: 7849.5 | J35: 2452 | L35: 2591.5 | O35: 5229 | Q35: 2462.5 | R35: 4879.5 | T35: 2801.6 | U35: 2572.02 | W35: 2607 | X35: 1796.75 | Y35: 4003.76 | Z35: 3058.57 | AA35: 2654.51 | AC35: 2221.78 | AD35: 2261.53 | AF35: 3126.91 | AH35: 1035 | AI35: 3165.5 | AK35: 2112 | AL35: 2766.01 | AM35: 2128 | AO35: 3029.5
A36: sábado | D36: 3659 | E36: 2701.5 | G36: 8039.52 | I36: 6272.5 | J36: 4101.5 | L36: 4350 | O36: 4470.03 | R36: 5251.02 | T36: 2807.51 | U36: 4090.01 | W36: 3276.02 | X36: 2694 | AA36: 3820.25 | AC36: 4849.76 | AD36: 2964.55 | AF36: 3471.5 | AI36: 2383.5 | AK36: 4380.5 | AL36: 3975.5 | AM36: 3662 | AO36: 4465
A37: domingo | D37: 2721 | G37: 7545.03 | J37: 5724 | L37: 0 | O37: 3468.12 | R37: 5516.01 | U37: 2706.52 | X37: 3085.75 | AA37: 3108 | AD37: 3844.15 | AF37: 4099.5 | AI37: 4227.5 | AM37: 4400.5 | AO37: 3762
A38: segunda-feira | G38: 2890 | J38: 2202.57 | U38: 3228.05 | X38: 2174.5 | AA38: 2419.5 | AD38: 1652.16 | AM38: 2178
A39: terça-feira | J39: 2904.5 | AM39: 2128
B47: Fevereiro | F47: Março | K47: Abril | P47: Maio | U47: Junho | Z47: Julho | AE47: Agosto | AJ47: Setembro | AO47: Outubro | AT47: Novembro | AY47: Dezembro | BD47: Janeiro | BI47: Fevereiro | BN47: Março | BS47: Abril | BX47: Maio | CC47: Junho | CH47: Julho | CM47: Agosto | CR47: Setembro | CW47: Outubro | DB47: Novembro | DG47: Dezembro | DL47: Janeiro | DQ47: Fevereiro | DV47: Março | EA47: Abril | EF47: Maio | EK47: Junho | EP47: Julho | EU47: Agosto | EZ47: Setembro | FE47: Outubro | FJ47: Novembro | FO47: Dezembro | FT47: Janeiro | FY47: Fevereiro | GC47: Março | GH47: Abril | GM47: Maio
A48: segunda-feira | B48: 2425.5 | C48: 1924.1 | D48: 4060.5 | E48: 4152.5 | G48: 1963.5 | H48: 1733 | I48: 2219 | J48: 2552.5 | L48: 2511 | M48: 2381.5 | N48: 2356.5 | O48: 1653 | Q48: 2641.5 | R48: 3488 | S48: 2666 | T48: 2192.5 | V48: 2131.5 | W48: 2140.5 | X48: 2145 | Y48: 2713.5 | Z48: 2610.5 | AA48: 2475 | AB48: 2881.01 | AC48: 4827 | AD48: 2890 | AF48: 2794.5 | AG48: 4478 | AH48: 2345.5 | AI48: 3324 | AK48: 2163.51 | AL48: 2128.01 | AM48: 2641.02 | AN48: 2475.5 | AO48: 2202.57 | AP48: 4109.51 | AQ48: 1880.5 | AR48: 3158 | AS48: 2368.5 | AU48: 1906 | AV48: 2463.52 | AW48: 6636.5 | AX48: 2362.5 | AZ48: 3183.53 | BA48: 3076 | BB48: 2293 | BC48: 2313 | BD48: 4329 | BE48: 2145.5 | BF48: 2846.51 | BG48: 3812.01 | BH48: 2831.53 | BJ48: 3300.63 | BK48: 3647.55 | BL48: 3044.52 | BM48: 5501.53 | BO48: 3477.02 | BP48: 3917.53 | BQ48: 2444.53 | BR48: 3259.51 | BS48: 2397.07 | BT48: 2049 | BU48: 3081.04 | BV48: 4340.04 | BW48: 2297.56 | BY48: 1989.07 | BZ48: 3067.68 | CA48: 2431.9 | CB48: 1731.01 | CD48: 2002.58 | CE48: 2220.52 | CF48: 2158.65 | CG48: 1687.05 | CH48: 2267.5 | CI48: 3263.04 | CJ48: 2651.58 | CK48: 2250.08 | CL48: 2989.59 | CN48: 2502.51 | CO48: 2737.7 | CQ48: 2664.13 | CR48: 2738.03 | CS48: 2681.05 | CT48: 2699.02 | CU48: 2559.01 | CV48: 3228.05 | CX48: 4573.11 | CY48: 1874.51 | CZ48: 5089.51 | DA48: 3520.01 | DC48: 2204.51 | DD48: 4360.75 | DE48: 4523.53 | DF48: 3022.25 | DG48: 3672.88 | DH48: 2929.75 | DI48: 2508 | DJ48: 2607.75 | DK48: 2174.5 | DM48: 2484 | DN48: 2271.75 | DO48: 4567.5 | DP48: 3328 | DR48: 2798.26 | DS48: 4290.77 | DT48: 3555.75 | DU48: 2615.5 | DV48: 2419.5 | DW48: 4028.76 | DX48: 2149.75 | DY48: 2571.51 | DZ48: 2315.75 | EB48: 2848.51 | EC48: 2065.51 | ED48: 2463.06 | EE48: 3103.76 | EG48: 2122.81 | EH48: 1417.26 | EI48: 2093.52 | EJ48: 2601.76 | EK48: 1652.16 | EL48: 1793 | EM48: 2079.5 | EN48: 1500.77 | EO48: 1438 | EQ48: 3226 | ER48: 1470.52 | ES48: 1729 | ET48: 1445.76 | EV48: 3270 | EW48: 2170.52 | EX48: 1835 | EY48: 1707.51 | EZ48: 3205.01 | FA48: 2873.5 | FB48: 2154.75 | FC48: 943.5 | FD48: 2091.01 | FF48: 4037.02 | FG48: 1076.01 | FH48: 2376.5 | FI48: 1874.5 | FK48: 2232 | FL48: 2552 | FM48: 1562.5 | FN48: 1871 | FO48: 3679 | FP48: 2690.5 | FQ48: 1849 | FR48: 2690.5 | FS48: 3029 | FU48: 2465 | FV48: 2547.5 | FW48: 2201.51 | FX48: 1805 | FY48: 2024.5 | FZ48: 3695 | GA48: 2008.5 | GB48: 1943 | GC48: 1674.5 | GD48: 2013.5 | GE48: 1635.5 | GF48: 1080 | GG48: 2178 | GI48: 1649.01 | GJ48: 1953 | GK48: 2595 | GL48: 1975 | GM48: 2540 | GN48: 1685 | GO48: 1406 | GP48: 3036.5
A49: terça-feira | B49: 4354 | C49: 2705.14 | D49: 3627.5 | E49: 4456.5 | G49: 2828.5 | H49: 3690 | I49: 2553.5 | J49: 2440.5 | L49: 2393.5 | M49: 1988 | N49: 4678.5 | O49: 2390 | Q49: 4765 | R49: 3590.5 | S49: 3580.5 | T49: 4254.5 | V49: 1955.5 | W49: 2227.5 | X49: 2556 | Y49: 3506 | Z49: 2460 | AA49: 3082.52 | AB49: 3468.5 | AC49: 6342.01 | AE49: 4263 | AF49: 3748.51 | AG49: 3859 | AH49: 3308.01 | AI49: 2423.5 | AK49: 5262.5 | AL49: 2463 | AM49: 2972 | AN49: 3361.5 | AO49: 2904.5 | AP49: 4020 | AQ49: 2136.59 | AR49: 2059.5 | AS49: 2282 | AU49: 3034.5 | AV49: 3122.5 | AW49: 2481 | AX49: 2935.53 | AZ49: 2779 | BA49: 3028.01 | BB49: 2868.5 | BC49: 3151.51 | BD49: 3538.5 | BE49: 2845 | BF49: 3897.01 | BG49: 4180 | BH49: 3881.01 | BJ49: 4051.51 | BK49: 4739.5 | BL49: 2547.53 | BM49: 6711.53 | BO49: 4959.07 | BP49: 5202 | BQ49: 4869.08 | BR49: 3560.5 | BS49: 3490.12 | BT49: 3501.51 | BU49: 3665.53 | BV49: 4233.52 | BW49: 3683.05 | BY49: 2624.08 | BZ49: 2663.59 | CA49: 2303.08 | CB49: 3429.01 | CD49: 2648.57 | CE49: 1779.11 | CF49: 2025.03 | CG49: 3827.66 | CH49: 3462.5 | CI49: 2942.51 | CJ49: 2505.5 | CK49: 2718.09 | CL49: 3831.03 | CN49: 2849.68 | CO49: 2837.1 | CP49: 2925.06 | CQ49: 3321.55 | CR49: 2823.51 | CS49: 2430.52 | CT49: 4766.03 | CU49: 2304.51 | CW49: 2892.04 | CX49: 4419.53 | CY49: 3094.03 | CZ49: 3999.38 | DA49: 2468.53 | DC49: 3185.51 | DD49: 5184.8 | DE49: 6178.52 | DF49: 2917.27 | DG49: 3349.51 | DH49: 2934.75 | DI49: 3633.6 | DM49: 3829.85 | DN49: 3730.25 | DO49: 3183.75 | DP49: 4182 | DR49: 3123.29 | DS49: 4036 | DT49: 3488.54 | DU49: 3972.76 | DW49: 3807.25 | DX49: 2203.75 | DY49: 2507.52 | DZ49: 2303.25 | EA49: 2152.27 | EB49: 1988.75 | EC49: 1480.76 | ED49: 2204.5 | EE49: 2110.78 | EG49: 2852.76 | EH49: 1942.27 | EI49: 2438 | EJ49: 2284.83 | EL49: 1909.01 | EM49: 2123.76 | EN49: 1245.76 | EO49: 1397.52 | EP49: 1645.71 | EQ49: 1465.51 | ER49: 2484.4 | ES49: 2054.54 | ET49: 2105.26 | EV49: 2543.54 | EW49: 3052 | EX49: 2066 | EY49: 2295 | EZ49: 2619 | FA49: 1530.5 | FB49: 1894.51 | FC49: 1312.52 | FD49: 2125.52 | FF49: 5475.01 | FG49: 2593.01 | FH49: 2089.5 | FI49: 835 | FK49: 1153.25 | FL49: 3252.5 | FM49: 1135.01 | FN49: 1636 | FO49: 2380 | FP49: 3328.5 | FQ49: 1986.51 | FR49: 1277.02 | FS49: 2334.51 | FU49: 2457.51 | FV49: 1989 | FW49: 7027.02 | FX49: 2564 | FY49: 2597.5 | FZ49: 3054.5 | GA49: 2237 | GB49: 2723.5 | GC49: 3251 | GD49: 2396 | GE49: 2055.5 | GF49: 2301 | GG49: 2128 | GI49: 1514 | GJ49: 2354.55 | GK49: 3196.5 | GL49: 2608.52 | GM49: 1781 | GN49: 2066 | GO49: 1741 | GP49: 1590.5
A50: quarta-feira | B50: 3910.81 | C50: 2399.9 | D50: 3655.62 | E50: 4146.5 | F50: 2935 | G50: 3716 | H50: 3608.5 | I50: 3062 | J50: 2898.31 | L50: 2022.5 | M50: 2640 | N50: 2052.5 | O50: 2691 | Q50: 4180.5 | R50: 2005.5 | S50: 3120.5 | T50: 2231 | V50: 3011.5 | W50: 3156.51 | X50: 2371 | Y50: 3397 | Z50: 2996.5 | AA50: 3377.5 | AB50: 3813 | AC50: 5435 | AE50: 3839.5 | AF50: 3880.5 | AG50: 3860.01 | AH50: 3837.04 | AI50: 3032.01 | AK50: 2961.01 | AL50: 3068 | AM50: 2657 | AN50: 3391 | AP50: 3080.5 | AQ50: 3153.51 | AR50: 3622.5 | AS50: 2955 | AT50: 3877.5 | AU50: 3194.02 | AV50: 8558.5 | AW50: 3232 | AX50: 2625 | AZ50: 2817.5 | BA50: 3176 | BB50: 2735.51 | BC50: 3852.5 | BD50: 3345.5 | BE50: 3176.51 | BF50: 3552.02 | BG50: 4146.5 | BH50: 3380 | BJ50: 3850 | BK50: 3983.03 | BL50: 3458.5 | BM50: 7669.51 | BO50: 4626.51 | BP50: 4511.03 | BQ50: 3148.57 | BR50: 3606.51 | BS50: 2457.5 | BT50: 3855.04 | BU50: 3542.58 | BV50: 2946.53 | BX50: 3035.03 | BY50: 2410.55 | BZ50: 2751.06 | CA50: 2339.07 | CB50: 2695.66 | CD50: 2459.08 | CE50: 3044.03 | CF50: 2132.57 | CG50: 3091.06 | CH50: 3879.05 | CI50: 2437.05 | CJ50: 3621.52 | CK50: 3490.5 | CL50: 2610.6 | CN50: 1872.57 | CO50: 3064.52 | CP50: 3664 | CQ50: 2664.13 | CR50: 2639.54 | CS50: 2415.5 | CT50: 3146.5 | CU50: 2470.5 | CW50: 3157.5 | CX50: 4276.57 | CY50: 2191.5 | CZ50: 1713.06 | DA50: 2949 | DC50: 2361.06 | DD50: 6840.76 | DE50: 7137.28 | DF50: 3455.25 | DG50: 2933 | DH50: 2933.75 | DI50: 2616 | DJ50: 1349.75 | DM50: 4595.25 | DN50: 3770.26 | DO50: 3561 | DP50: 4014.01 | DR50: 3196.5 | DS50: 5012.26 | DT50: 4198.01 | DU50: 3786.25 | DW50: 3865.78 | DX50: 3651 | DY50: 2404.02 | DZ50: 3328.25 | EA50: 2586.75 | EB50: 2392 | EC50: 3039 | ED50: 2588.51 | EE50: 3014.75 | EG50: 2315.5 | EH50: 2700 | EI50: 2086.76 | EJ50: 2608.02 | EL50: 2132.76 | EM50: 2997.75 | EN50: 2614.03 | EO50: 2021.76 | EP50: 2767.5 | EQ50: 2495.5 | ER50: 2447.5 | ES50: 2148.03 | ET50: 2285.01 | EV50: 2101.01 | EW50: 3561.52 | EX50: 1960 | EY50: 3937.5 | EZ50: 2668.51 | FA50: 2097.29 | FB50: 2338.51 | FC50: 2002.04 | FE50: 1866.01 | FF50: 7205.5 | FG50: 2003.52 | FH50: 2055.5 | FI50: 2232.03 | FK50: 2083.5 | FL50: 1830.5 | FM50: 2343.01 | FN50: 2386 | FO50: 3015.02 | FP50: 2934.01 | FQ50: 1610 | FU50: 3659 | FV50: 3473.04 | FW50: 1784 | FX50: 4048.5 | FY50: 2935.91 | FZ50: 4457 | GA50: 1707.5 | GB50: 2723.5 | GC50: 2356 | GD50: 5202 | GE50: 1266 | GF50: 2330.5 | GH50: 1454 | GI50: 2793 | GJ50: 2607.51 | GK50: 2064.5 | GL50: 3424.5 | GM50: 3419.5 | GN50: 3548 | GO50: 1648 | GP50: 3014.5
A51: quinta-feira | B51: 2479.32 | C51: 3475.38 | D51: 2025 | E51: 2418.5 | F51: 2988 | G51: 2288.5 | H51: 2119.5 | I51: 2894.5 | J51: 3012 | L51: 2776 | M51: 2426.5 | N51: 2868 | O51: 2403.5 | P51: 3650 | Q51: 1962 | R51: 2120.5 | S51: 1309.5 | T51: 2854.5 | U51: 2119 | V51: 4296 | W51: 2657.51 | X51: 3537.5 | Y51: 2585.51 | Z51: 2261.52 | AA51: 3606.02 | AB51: 5307.02 | AC51: 4686 | AE51: 4248.04 | AF51: 2187.51 | AG51: 2902.5 | AH51: 3837.04 | AI51: 4048.52 | AK51: 4629 | AL51: 2362 | AM51: 2459.01 | AN51: 2520.05 | AP51: 2868.01 | AQ51: 6548.5 | AR51: 3047.01 | AS51: 2615 | AT51: 6601.53 | AU51: 3569.03 | AV51: 2608.5 | AW51: 2389.51 | AX51: 3455 | AZ51: 3965.53 | BA51: 3841.51 | BB51: 3217.03 | BC51: 4043 | BD51: 2988.51 | BE51: 3624.04 | BF51: 2445.5 | BG51: 4785.02 | BI51: 4371.62 | BJ51: 2967.53 | BK51: 4318.03 | BL51: 5258.01 | BM51: 4429.56 | BO51: 4090.51 | BP51: 2940.52 | BQ51: 4010.03 | BR51: 3487.53 | BS51: 4090.51 | BT51: 4783.54 | BU51: 3078.1 | BV51: 2552.55 | BX51: 2139.02 | BY51: 2216.54 | BZ51: 2984.53 | CA51: 2740.55 | CB51: 2140.55 | CD51: 1952.52 | CE51: 2266.57 | CF51: 2538.53 | CG51: 3403.54 | CH51: 3291 | CI51: 3111.5 | CJ51: 2359.5 | CK51: 3646.03 | CM51: 2321.08 | CN51: 3432.62 | CO51: 2748.05 | CP51: 2935.13 | CQ51: 3207.61 | CR51: 1626.01 | CS51: 2605.52 | CT51: 1952.02 | CU51: 2039.5 | CW51: 2555.52 | CX51: 4676.55 | CY51: 2777.54 | CZ51: 2836.53 | DA51: 3705.03 | DC51: 5680.52 | DD51: 3973.78 | DE51: 3774.76 | DF51: 5585.51 | DG51: 2908 | DH51: 2501.6 | DI51: 2690.81 | DJ51: 2033.5 | DL51: 2801.25 | DM51: 3879.5 | DN51: 3424.02 | DO51: 3948.5 | DP51: 3410.67 | DR51: 4774.27 | DS51: 4701.75 | DT51: 3899.51 | DU51: 2676.76 | DW51: 4310.26 | DX51: 3370.25 | DY51: 2565.5 | DZ51: 3336.29 | EA51: 1924.01 | EB51: 2441.01 | EC51: 2141.04 | ED51: 1523.75 | EF51: 4156.01 | EG51: 2369.26 | EH51: 2343 | EI51: 2587.26 | EJ51: 1925.53 | EL51: 1690.26 | EM51: 3996.29 | EN51: 2380.75 | EO51: 1648.5 | EP51: 2230.26 | EQ51: 3523.02 | ER51: 2762.5 | ES51: 3636.1 | ET51: 2123.8 | EV51: 2547.42 | EW51: 2677.52 | EX51: 4493 | EY51: 2547 | EZ51: 2248.51 | FA51: 2250 | FB51: 1838 | FC51: 2439 | FE51: 3476.5 | FF51: 7879.81 | FG51: 2930.52 | FH51: 1910.5 | FI51: 1986 | FK51: 3006.26 | FL51: 2209 | FM51: 3377.51 | FN51: 3025.52 | FO51: 3900.5 | FP51: 2524 | FQ51: 2127.5 | FR51: 941.02 | FT51: 2674 | FU51: 2701.5 | FV51: 2970 | FW51: 4027.53 | FX51: 3109 | FY51: 3079.5 | FZ51: 1257 | GA51: 1749.5 | GB51: 2439.5 | GC51: 1897.5 | GD51: 2442.5 | GE51: 2001.5 | GF51: 1821.5 | GH51: 1926.5 | GI51: 2022.5 | GJ51: 1818.5 | GK51: 3013.5 | GL51: 2596.5 | GM51: 3043.5 | GN51: 1981.53 | GO51: 1950.5 | GP51: 2225
A52: sexta-feira | B52: 4701.23 | C52: 4031.92 | D52: 2346.5 | E52: 3142 | F52: 3214 | G52: 3160.5 | H52: 3235.5 | I52: 2850 | J52: 7191.5 | L52: 4051.5 | M52: 6451 | N52: 4995.5 | O52: 3068 | P52: 2156 | Q52: 2081.5 | R52: 2688 | S52: 2044.5 | T52: 3672 | U52: 2262 | V52: 3098.5 | W52: 2385.02 | X52: 3413.5 | Y52: 2997.01 | Z52: 2952.01 | AA52: 3082.5 | AB52: 5198.5 | AC52: 4838.01 | AE52: 4161.51 | AF52: 2958 | AG52: 2904 | AH52: 3264.02 | AJ52: 2905.5 | AK52: 3444 | AL52: 3320.5 | AM52: 4058.5 | AN52: 7849.5 | AP52: 3473.51 | AQ52: 6433 | AR52: 4769 | AS52: 2452 | AT52: 3818.04 | AU52: 3728.02 | AV52: 3220 | AW52: 3746.5 | AY52: 4192.5 | AZ52: 3688 | BA52: 2814.01 | BB52: 3927 | BC52: 2591.5 | BD52: 3696 | BE52: 3733.53 | BF52: 3505.01 | BG52: 5060.5 | BI52: 4086.52 | BJ52: 3114.53 | BK52: 5971.5 | BL52: 6791.08 | BN52: 5660.52 | BO52: 6856.5 | BP52: 3841.5 | BQ52: 2485.05 | BR52: 5229 | BS52: 3500.52 | BT52: 3759.54 | BU52: 3223 | BV52: 3727.06 | BX52: 1931.02 | BY52: 2109.57 | BZ52: 2660.53 | CA52: 1891.01 | CB52: 2462.5 | CD52: 2451.6 | CE52: 3083.04 | CF52: 2749.59 | CG52: 4879.5 | CH52: 2809.01 | CI52: 2512.56 | CJ52: 3186.5 | CK52: 2198.1 | CM52: 2473.12 | CN52: 2343.63 | CO52: 1730 | CP52: 2231.05 | CQ52: 2801.6 | CR52: 2656.51 | CS52: 2431.5 | CT52: 2626.01 | CU52: 2572.02 | CW52: 6734.42 | CX52: 4732.57 | CY52: 2639.51 | CZ52: 2337.5 | DB52: 2717.01 | DC52: 6553.12 | DD52: 8689.26 | DE52: 3855.02 | DF52: 2607 | DG52: 2907.85 | DH52: 3563.35 | DI52: 2366 | DJ52: 1796.75 | DL52: 2801.51 | DM52: 2982.75 | DN52: 2989.75 | DO52: 6062.25 | DP52: 4003.76 | DR52: 5214.75 | DS52: 3829.5 | DT52: 4059.45 | DU52: 3058.57 | DW52: 4051.5 | DX52: 2659.01 | DY52: 3666.75 | DZ52: 2654.51 | EA52: 2322.27 | EB52: 3065.81 | EC52: 1976.5 | ED52: 3375.5 | EF52: 3059.75 | EG52: 2985.26 | EH52: 2099.76 | EI52: 3058.25 | EJ52: 2221.78 | EL52: 2939.29 | EM52: 1930.5 | EN52: 1809.59 | EO52: 2261.53 | EP52: 3552.76 | EQ52: 3388.5 | ER52: 2244.27 | ES52: 1866.5 | EU52: 1669 | EV52: 1932.5 | EW52: 2163.5 | EX52: 2014 | EY52: 3126.91 | EZ52: 1568 | FA52: 2097.93 | FB52: 1633.01 | FC52: 2878.92 | FE52: 5068.51 | FF52: 6661.76 | FG52: 1796.5 | FH52: 2070.75 | FI52: 1035 | FK52: 3303.75 | FL52: 2235 | FM52: 2239 | FN52: 3165.5 | FO52: 2976.01 | FP52: 2651 | FQ52: 1266 | FR52: 1994.01 | FT52: 4655.5 | FU52: 3397.5 | FV52: 3421.5 | FW52: 3482 | FX52: 2112 | FY52: 2657.5 | FZ52: 1471.5 | GA52: 2585.4 | GB52: 2766.01 | GC52: 2130.5 | GD52: 2079 | GE52: 2674 | GF52: 2128 | GH52: 2649 | GI52: 2358 | GJ52: 2350.5 | GK52: 2211 | GM52: 1952 | GN52: 1924 | GO52: 2996 | GP52: 3029.5 | GQ52: 6527.5
A53: sábado | B53: 6723.1 | C53: 5536.05 | D53: 3673 | E53: 4052.5 | F53: 4675.5 | G53: 5589.5 | H53: 4443 | I53: 3524.5 | K53: 4355 | L53: 5664.5 | M53: 4568.5 | N53: 4507 | O53: 3659 | P53: 2190 | Q53: 2482 | R53: 2466.5 | S53: 2214 | T53: 2701.5 | U53: 4739.5 | V53: 3258.5 | W53: 5408.51 | X53: 4097.51 | Z53: 2952.01 | AA53: 3862 | AB53: 5675.02 | AC53: 8039.52 | AD53: 3232.5 | AE53: 6064 | AF53: 4542.01 | AG53: 5272 | AH53: 4555.02 | AJ53: 5756 | AK53: 4754.01 | AL53: 3240.5 | AM53: 5241 | AN53: 6272.5 | AP53: 6836 | AQ53: 7005 | AR53: 5458 | AS53: 4101.5 | AT53: 2671 | AU53: 4232 | AV53: 6592.5 | AW53: 5092.5 | AY53: 5839.52 | AZ53: 5054.5 | BA53: 4268.03 | BB53: 2734.5 | BC53: 4350 | BD53: 5441.55 | BE53: 5902.04 | BF53: 6416.01 | BG53: 7409.01 | BI53: 8196.01 | BJ53: 4429.56 | BK53: 7659.03 | BL53: 8037.5 | BN53: 7785.52 | BO53: 7348.01 | BP53: 7511.1 | BQ53: 5373.52 | BR53: 4470.03 | BS53: 5998.03 | BT53: 5133.04 | BU53: 4206.56 | BV53: 5224.52 | BX53: 2095.53 | BY53: 2295.52 | BZ53: 2511.53 | CA53: 3675.05 | CC53: 2436.04 | CD53: 2090 | CE53: 2458.84 | CF53: 4177.03 | CG53: 5251.02 | CH53: 3387.03 | CI53: 3434.54 | CJ53: 2792.03 | CK53: 3770.53 | CM53: 2189.54 | CN53: 3024.06 | CO53: 3810.52 | CP53: 3168.51 | CQ53: 2807.51 | CR53: 3874 | CS53: 3454.51 | CT53: 3730.5 | CU53: 4090.01 | CW53: 7501.06 | CX53: 5725.01 | CY53: 2003.5 | CZ53: 3618.5 | DB53: 3755.01 | DC53: 8614 | DD53: 8072.52 | DE53: 6697.26 | DF53: 3276.02 | DG53: 3392.75 | DH53: 2487 | DI53: 2478.75 | DJ53: 2694 | DL53: 4097.75 | DM53: 5174 | DN53: 5551.52 | DO53: 6062.25 | DQ53: 5627.25 | DR53: 6359.77 | DS53: 5093.75 | DT53: 5634.5 | DV53: 4655 | DW53: 6328.75 | DX53: 4990.75 | DY53: 5398.77 | DZ53: 3820.25 | EA53: 2719.76 | EB53: 3065.25 | EC53: 3048.54 | ED53: 4911 | EF53: 3847.75 | EG53: 3706.01 | EH53: 3700 | EI53: 5817.01 | EJ53: 4849.76 | EL53: 3811.75 | EM53: 3716.29 | EN53: 2224 | EO53: 2964.55 | EP53: 2805 | EQ53: 4008.16 | ER53: 2244.5 | ES53: 2461.5 | EU53: 3284.15 | EV53: 3584.42 | EW53: 3196.9 | EX53: 3132.9 | EY53: 3471.5 | EZ53: 3452.51 | FA53: 3593.8 | FB53: 2976.67 | FC53: 3228.5 | FE53: 5921.51 | FF53: 8622 | FG53: 3029.9 | FH53: 4417.25 | FJ53: 4149.5 | FK53: 5357.5 | FL53: 3360.5 | FM53: 2282.5 | FN53: 2383.5 | FO53: 4037.5 | FP53: 4429.01 | FQ53: 3522 | FR53: 2806.51 | FT53: 5409.5 | FU53: 5844.01 | FV53: 5946 | FW53: 6372 | FX53: 4380.5 | FY53: 5130 | FZ53: 3689.5 | GA53: 4992.01 | GB53: 3975.5 | GC53: 3652.01 | GD53: 2945.5 | GE53: 3262.5 | GF53: 3662 | GH53: 4476.5 | GI53: 4750.5 | GJ53: 4164.5 | GK53: 2959.51 | GM53: 6028.06 | GN53: 6114 | GO53: 3912 | GP53: 4465 | GQ53: 3245.5
A54: domingo | B54: 5052.11 | C54: 5480.5 | D54: 3671 | E54: 4736 | F54: 5030 | G54: 4383 | H54: 3675.5 | I54: 2552.5 | K54: 4468.5 | L54: 3716 | M54: 3877.5 | N54: 3237.5 | O54: 2721 | P54: 2986 | Q54: 2258 | R54: 2666 | S54: 2214 | U54: 3980.5 | V54: 3123.5 | W54: 3754.5 | X54: 4193.5 | Z54: 4798.5 | AA54: 3467 | AB54: 6820 | AC54: 7545.03 | AD54: 3942.5 | AE54: 4671.02 | AF54: 3816.5 | AG54: 4979.01 | AH54: 4701.5 | AJ54: 4584.01 | AK54: 3477.13 | AL54: 3979.51 | AM54: 3710.5 | AO54: 7505 | AP54: 4521 | AQ54: 6027 | AR54: 5944 | AS54: 5724 | AT54: 4268.02 | AU54: 6334.5 | AV54: 5898 | AW54: 4474 | AY54: 4675.5 | AZ54: 6274 | BA54: 4159.5 | BD54: 4982 | BE54: 6163.5 | BF54: 4838.09 | BG54: 8351 | BI54: 6234.5 | BJ54: 5069.52 | BK54: 7680.01 | BL54: 10609.51 | BN54: 7755.51 | BO54: 7547.04 | BP54: 6691.53 | BQ54: 4384 | BR54: 3468.12 | BS54: 4436.54 | BT54: 4879.5 | BU54: 4285.06 | BV54: 4299.09 | BX54: 3064.05 | BY54: 2134.07 | BZ54: 2559.55 | CA54: 2337.51 | CC54: 1830 | CD54: 1864.57 | CE54: 1920.53 | CF54: 5134.57 | CG54: 5516.01 | CH54: 3640 | CI54: 2638.06 | CJ54: 2969 | CK54: 2330.57 | CM54: 2452.03 | CN54: 1972.08 | CO54: 2209.51 | CP54: 3691.09 | CR54: 2695.5 | CS54: 2628.53 | CT54: 3346 | CU54: 2706.52 | CV54: 2102 | CW54: 5339.56 | CX54: 6097.03 | CY54: 3688.5 | CZ54: 4389.5 | DB54: 2770.5 | DC54: 8551.27 | DD54: 6901.26 | DE54: 5108.8 | DG54: 2658.25 | DH54: 3171.75 | DI54: 2270.5 | DJ54: 3085.75 | DK54: 3470.75 | DL54: 3457.81 | DM54: 3844.25 | DN54: 5499.75 | DO54: 5242.77 | DQ54: 4641.26 | DR54: 7420.75 | DS54: 4808.85 | DT54: 4964.25 | DV54: 3510.53 | DW54: 5694.01 | DX54: 4930.04 | DY54: 4646.25 | DZ54: 3108 | EA54: 3215.25 | EB54: 2786.01 | EC54: 1359 | ED54: 2492.02 | EF54: 3424.27 | EG54: 2910.75 | EH54: 2456.5 | EI54: 4526 | EK54: 4180.83 | EL54: 4635.29 | EM54: 2684.02 | EN54: 2497.59 | EO54: 3844.15 | EP54: 3583.24 | EQ54: 2679.07 | ER54: 2258.2 | ES54: 3170.15 | EU54: 3413.9 | EV54: 3536.91 | EW54: 2686.8 | EX54: 1980 | EY54: 4099.5 | EZ54: 3052.5 | FA54: 2751 | FB54: 2882.9 | FC54: 3071 | FE54: 6536.4 | FF54: 7934.7 | FG54: 4194.4 | FH54: 2996.41 | FJ54: 3339.9 | FK54: 5717.4 | FL54: 3765.41 | FM54: 2556.5 | FN54: 4227.5 | FO54: 3251.01 | FP54: 2350.5 | FQ54: 2802.5 | FR54: 3695.5 | FT54: 5360.01 | FU54: 5247 | FV54: 6474 | FW54: 5614.5 | FY54: 7023.5 | FZ54: 2867.5 | GA54: 2943.5 | GB54: 6048.5 | GC54: 3740.5 | GD54: 2583 | GE54: 3460 | GF54: 4400.5 | GG54: 3500.5 | GH54: 2620.5 | GI54: 4090 | GJ54: 4225 | GK54: 3206 | GM54: 3823 | GN54: 4655 | GO54: 3848 | GP54: 3762 | GQ54: 6348
B56: Máximo | C56: Mínimo | D56: Dias | E56: Média | F56: Ponderada | G56: Crescimento
A57: segunda-feira | B57: =MAX(FO48:GQ48) -> 3695 | C57: =MIN(FO48:GQ48) -> 1080 | D57: =COUNTA(FO48:GQ48) -> 26 | E57: =SUM(FO48:GQ48)/D57 -> 2232.6546 | F57: =(SUM(FO48:GQ48)-B57-C57)/(D57-2) -> 2219.7508 | G57: =F57*1.1 -> 2441.7259
A58: terça-feira | B58: =MAX(FO49:GQ49) -> 7027.02 | C58: =MIN(FO49:GQ49) -> 1277.02 | D58: =COUNTA(FO49:GQ49) -> 26 | E58: =SUM(FO49:GQ49)/D58 -> 2497.6977 | F58: =(SUM(FO49:GQ49)-B58-C58)/(D58-2) -> 2359.8375 | G58: =F58*1.1 -> 2595.8212
A59: quarta-feira | B59: =MAX(FO50:GQ50) -> 5202 | C59: =MIN(FO50:GQ50) -> 1266 | D59: =COUNTA(FO50:GQ50) -> 24 | E59: =SUM(FO50:GQ50)/D59 -> 2811.4788 | F59: =(SUM(FO50:GQ50)-B59-C59)/(D59-2) -> 2773.0677 | G59: =F59*1.1 -> 3050.3745
A60: quinta-feira | B60: =MAX(FO51:GQ51) -> 4027.53 | C60: =MIN(FO51:GQ51) -> 941.02 | D60: =COUNTA(FO51:GQ51) -> 26 | E60: =SUM(FO51:GQ51)/D60 -> 2393.9069 | F60: =(SUM(FO51:GQ51)-B60-C60)/(D60-2) -> 2386.3762 | G60: =F60*1.1 -> 2625.0139
...

Sheet Anteriores
A1: 44958 | G1: 44986 | M1: 45017 | S1: 45047 | Y1: 45078 | AE1: 45108 | AK1: 45139 | AQ1: 45170 | AW1: 45200 | BC1: 45231 | BI1: 45261 | BO1: 45292 | BU1: 45323 | CA1: 45352 | CG1: 45383 | CM1: 45413 | CS1: 45444 | CY1: 45474 | DE1: 45505 | DK1: 45536 | DQ1: 45566 | DW1: 45597 | EC1: 45627 | EI1: 45658 | EO1: 45689 | EU1: 45717 | FA1: 45748 | FG1: 45778 | FM1: 45809 | FS1: 45839 | FY1: 45870 | GE1: 45901 | GK1: 45931 | GQ1: 45962 | GW1: 45992 | HC1: 46023 | HI1: 46054 | HO1: 46082 | HU1: 46113 | IA1: 46143
A2: Dia | C2: Meta | D2: Realizado | E2: % | G2: Dia | I2: Meta | J2: Realizado | K2: % | M2: Dia | O2: Meta | P2: Realizado | Q2: % | S2: Dia | U2: Meta | V2: Realizado | W2: % | Y2: Dia | AA2: Meta | AB2: Realizado | AE2: Dia | AG2: Meta | AH2: Realizado | AK2: Dia | AM2: Meta | AN2: Realizado | AQ2: Dia | AS2: Meta | AT2: Realizado | AW2: Dia | AY2: Meta | AZ2: Realizado | BC2: Dia | BE2: Meta | BF2: Realizado | BI2: Dia | BK2: Meta | BL2: Realizado | BO2: Dia | BQ2: Meta | BR2: Realizado | BU2: Dia | BW2: Meta | BX2: Realizado | CA2: Dia | CC2: Meta | CD2: Realizado | CG2: Dia | CI2: Meta | CJ2: Realizado | CM2: Dia | CO2: Meta | CP2: Realizado | CS2: Dia | CU2: Meta | CV2: Realizado | CY2: Dia | DA2: Meta | DB2: Realizado | DE2: Dia | DG2: Meta | DH2: Realizado | DK2: Dia | DM2: Meta | DN2: Realizado | DQ2: Dia | DS2: Meta | DT2: Realizado | DW2: Dia | DY2: Meta | DZ2: Realizado | EC2: Dia | EE2: Meta | EF2: Realizado | EI2: Dia | EK2: Meta | EL2: Realizado | EM2: % | EO2: Dia | EQ2: Meta | ER2: Realizado | ES2: % | EU2: Dia | EW2: Meta | EX2: Realizado | EY2: % | FA2: Dia | FC2: Meta | FD2: Realizado | FE2: % | FG2: Dia | FI2: Meta | FJ2: Realizado | FK2: % | FM2: Dia | FO2: Meta | FP2: Realizado | FQ2: % | FS2: Dia | FU2: Meta | FV2: Realizado | FW2: % | FY2: Dia | GA2: Meta | GB2: Realizado | GC2: % | GE2: Dia | GG2: Meta | GH2: Realizado | GI2: % | GK2: Dia | GM2: Meta | GN2: Realizado | GO2: % | GQ2: Dia | GS2: Meta | GT2: Realizado | GU2: % | GW2: Dia | GY2: Meta | GZ2: Realizado | HA2: % | HC2: Dia | HE2: Meta | HF2: Realizado | HG2: % | HI2: Dia | HK2: Meta | HL2: Realizado | HM2: % | HO2: Dia | HQ2: Meta | HR2: Realizado | HS2: % | HU2: Dia | HW2: Meta | HX2: Realizado | HY2: % | IA2: Dia | IC2: Meta | ID2: Realizado | IE2: %
A3: 1 | B3: quarta-feira | C3: 3500 | D3: 3910.81 | E3: =D3/C3 -> 1.1173743 | G3: 1 | H3: quarta-feira | I3: 3528.2075 | J3: 2935 | K3: =J3/I3 -> 0.83186717 | M3: 1 | N3: sábado | O3: 4968.2295 | P3: 4355 | Q3: =P3/O3 -> 0.87656981 | S3: 1 | T3: segunda-feira | U3: 2494.3833 | V3: 3650 | W3: =V3/U3 -> 1.4632875 | Y3: 1 | Z3: quinta-feira | AA3: 2559.5111 | AB3: 2119 | AC3: =AB3/AA3 -> 0.82789248 | AE3: 1 | AF3: sábado | AG3: 4238.4111 | AH3: 3232.5 | AI3: =AH3/AG3 -> 0.76266787 | AK3: 1 | AL3: terça-feira | AM3: 3417.1133 | AN3: 4263 | AO3: =AN3/AM3 -> 1.2475442 | AQ3: 1 | AR3: sexta-feira | AS3: 3514.6392 | AT3: 2905.5 | AU3: =AT3/AS3 -> 0.82668515 | AW3: 1 | AX3: domingo | AY3: 4746.3119 | AZ3: 7505 | BA3: =AZ3/AY3 -> 1.5812277 | BC3: 1 | BD3: quarta-feira | BE3: 3500.343 | BF3: 3877.5 | BG3: =BF3/BE3 -> 1.1077486 | BI3: 1 | BJ3: sexta-feira | BK3: 4128.831 | BL3: 4192.5 | BM3: =BL3/BK3 -> 1.0154206 | BO3: 1 | BP3: segunda-feira | BQ3: 3068.6928 | BR3: 4329 | BS3: =BR3/BQ3 -> 1.4106984 | BU3: 1 | BV3: quinta-feira | BW3: 3978.4726 | BX3: 4371.62 | BY3: =BX3/BW3 -> 1.0988187 | CA3: 1 | CB3: sexta-feira | CC3: 4398.807 | CD3: 5660.52 | CE3: =CD3/CC3 -> 1.2868307 | CG3: 1 | CH3: segunda-feira | CI3: 3421.8469 | CJ3: 2397.07 | CK3: =CJ3/CI3 -> 0.70051937 | CM3: 1 | CN3: quarta-feira | CO3: 4042.7809 | CP3: 3035.03 | CQ3: =CP3/CO3 -> 0.7507283 | CS3: 1 | CT3: sábado | CU3: 5622.4805 | CV3: 2436.04 | CW3: =CV3/CU3 -> 0.43326784 | CY3: 1 | CZ3: segunda-feira | DA3: 2939.2712 | DB3: 2267.5 | DC3: =DB3/DA3 -> 0.77144974 | DE3: 1 | DF3: quinta-feira | DG3: 3410.6577 | DH3: 2321.08 | DI3: =DH3/DG3 -> 0.68053737 | DK3: 1 | DL3: domingo | DM3: 3817.0635 | DN3: 2102 | DO3: =DN3/DM3 -> 0.5506851 | DQ3: 1 | DR3: terça-feira | DS3: 3195.7761 | DT3: 2892.04 | DU3: =DT3/DS3 -> 0.90495703 | DW3: 1 | DX3: sexta-feira | DY3: 3392.4293 | DZ3: 2717.01 | EA3: =DZ3/DY3 -> 0.80090393 | EC3: 1 | ED3: domingo | EE3: 4361.2149 | EF3: 3470.75 | EG3: =EF3/EE3 -> 0.79582182 | EI3: 1 | EJ3: quarta-feira | EO3: 1 | EP3: sábado | EQ3: 4710.9641 | ER3: 5627.25 | ES3: =ER3/EQ3 -> 1.1945007 | EU3: 1 | EV3: sábado | EW3: 5238.8684 | EX3: 4655 | EY3: =EX3/EW3 -> 0.88855067 | FA3: 1 | FB3: terça-feira | FC3: 3878.677 | FD3: 2152.27 | FE3: =FD3/FC3 -> 0.55489797 | FG3: 1 | FH3: quinta-feira | FI3: 3926.0768 | FJ3: 4156.01 | FK3: =FJ3/FI3 -> 1.0585656 | FM3: 1 | FN3: domingo | FO3: 4213.6482 | FP3: 4180.83 | FQ3: =FP3/FO3 -> 0.99221146 | FS3: 1 | FT3: terça-feira | FU3: 2925.9639 | FV3: 1645.71 | FW3: =FV3/FU3 -> 0.56245054 | FY3: 1 | FZ3: sexta-feira | GA3: 3374.1856 | GB3: 1669 | GC3: =GB3/GA3 -> 0.49463788 | GE3: 1 | GF3: segunda-feira | GG3: 2544.1185 | GH3: 3205.01 | GI3: =GH3/GG3 -> 1.2597723 | GK3: 1 | GL3: quarta-feira | GM3: 3098.3747 | GN3: 1866.01 | GO3: =GN3/GM3 -> 0.60225447 | GQ3: 1 | GR3: sábado | GS3: 4984.5623 | GT3: 4149.5 | GU3: =GT3/GS3 -> 0.83247029 | GW3: 1 | GX3: segunda-feira | GY3: 2356.8541 | GZ3: 3679 | HA3: =GZ3/GY3 -> 1.5609791 | HC3: 1 | HD3: quinta-feira | HE3: 3129.2094 | HF3: 2674 | HG3: =HF3/HE3 -> 0.85452894 | HI3: 1 | HJ3: domingo | HK3: 4579.572 | HL3: 6048.5 | HM3: =HL3/HK3 -> 1.3207566 | HO3: 1 | HP3: domingo | HQ3: 4694.9778 | HR3: 3500.5 | HS3: =HR3/HQ3 -> 0.74558394 | HU3: 1 | HV3: quarta-feira | HW3: 2951.8025 | HX3: 1454 | HY3: =HX3/HW3 -> 0.49258038 | IA3: 1 | IB3: sexta-feira | IC3: 2874.8783 | ID3: 6527.5 | IE3: =ID3/IC3 -> 2.2705309
A4: 2 | B4: quinta-feira | C4: 2800 | D4: 2479.32 | E4: =D4/C4 -> 0.88547143 | G4: 2 | H4: quinta-feira | I4: 2599.55 | J4: 2988 | K4: =J4/I4 -> 1.1494297 | M4: 2 | N4: domingo | O4: 4495.4793 | P4: 4468.5 | Q4: =P4/O4 -> 0.99399857 | S4: 2 | T4: terça-feira | U4: 3175.47 | V4: 2156 | W4: =V4/U4 -> 0.67895461 | Y4: 2 | Z4: sexta-feira | AA4: 3615.6194 | AB4: 2262 | AC4: =AB4/AA4 -> 0.62561894 | AE4: 2 | AF4: domingo | AG4: 3814.7821 | AH4: 3942.5 | AI4: =AH4/AG4 -> 1.0334797 | AK4: 2 | AL4: quarta-feira | AM4: 3259.2753 | AN4: 3839.5 | AO4: =AN4/AM4 -> 1.1780226 | AQ4: 2 | AR4: sábado | AS4: 4983.3081 | AT4: 5756 | AU4: =AT4/AS4 -> 1.155056 | AW4: 2 | AX4: segunda-feira | AY4: 2984.1708 | AZ4: 4109.51 | BA4: =AZ4/AY4 -> 1.3771028 | BC4: 2 | BD4: quinta-feira | BE4: 3575.8307 | BF4: 6601.53 | BG4: =BF4/BE4 -> 1.8461528 | BI4: 2 | BJ4: sábado | BK4: 5319.0418 | BL4: 5839.52 | BM4: =BL4/BK4 -> 1.0978519 | BO4: 2 | BP4: terça-feira | BQ4: 3384.925 | BR4: 3538.5 | BS4: =BR4/BQ4 -> 1.0453703 | BU4: 2 | BV4: sexta-feira | BW4: 4231.4641 | BX4: 4086.52 | BY4: =BX4/BW4 -> 0.96574611 | CA4: 2 | CB4: sábado | CC4: 5912.077 | CD4: 7785.52 | CE4: =CD4/CC4 -> 1.3168841 | CG4: 2 | CH4: terça-feira | CI4: 3787.9865 | CJ4: 3490.12 | CK4: =CJ4/CI4 -> 0.92136549 | CM4: 2 | CN4: quinta-feira | CO4: 4144.624 | CP4: 2139.02 | CQ4: =CP4/CO4 -> 0.51609507 | CS4: 2 | CT4: domingo | CU4: 5211.9011 | CV4: 1830 | CW4: =CV4/CU4 -> 0.35111948 | CY4: 2 | CZ4: terça-feira | DA4: 3688.5249 | DB4: 3462.5 | DC4: =DB4/DA4 -> 0.93872216 | DE4: 2 | DF4: sexta-feira | DG4: 3693.5211 | DH4: 2473.12 | DI4: =DH4/DG4 -> 0.66958328 | DK4: 2 | DL4: segunda-feira | DM4: 2758.3412 | DN4: 2738.03 | DO4: =DN4/DM4 -> 0.99263644 | DQ4: 2 | DR4: quarta-feira | DS4: 3018.0552 | DT4: 3157.5 | DU4: =DT4/DS4 -> 1.0462035 | DW4: 2 | DX4: sábado | DY4: 4387.43 | DZ4: 3755.01 | EA4: =DZ4/DY4 -> 0.85585639 | EC4: 2 | ED4: segunda-feira | EE4: 3478.477 | EF4: 3672.88 | EG4: =EF4/EE4 -> 1.0558874 | EI4: 2 | EJ4: quinta-feira | EK4: 3270.1531 | EL4: 2801.25 | EM4: =EL4/EK4 -> 0.85661127 | EO4: 2 | EP4: domingo | EQ4: 4203.3225 | ER4: 4641.26 | ES4: =ER4/EQ4 -> 1.1041884 | EU4: 2 | EV4: domingo | EW4: 4690.301 | EX4: 3510.53 | EY4: =EX4/EW4 -> 0.74846582 | FA4: 2 | FB4: quarta-feira | FC4: 3929.0711 | FD4: 2586.75 | FE4: =FD4/FC4 -> 0.65836172 | FG4: 2 | FH4: sexta-feira | FI4: 4211.0293 | FJ4: 3059.75 | FK4: =FJ4/FI4 -> 0.72660382 | FM4: 2 | FN4: segunda-feira | FO4: 3046.4022 | FP4: 1793 | FQ4: =FP4/FO4 -> 0.58856313 | FS4: 2 | FT4: quarta-feira | FU4: 3453.1279 | FV4: 2767.5 | FW4: =FV4/FU4 -> 0.80144729 | FY4: 2 | FZ4: sábado | GA4: 4768.5024 | GB4: 3284.15 | GC4: =GB4/GA4 -> 0.68871728 | GE4: 2 | GF4: terça-feira | GG4: 2506.3233 | GH4: 2619 | GI4: =GH4/GG4 -> 1.044957 | GK4: 2 | GL4: quinta-feira | GM4: 3151.4242 | GN4: 3476.5 | GO4: =GN4/GM4 -> 1.103152 | GQ4: 2 | GR4: domingo | GS4: 4423.4333 | GT4: 3339.9 | GU4: =GT4/GS4 -> 0.75504698 | GW4: 2 | GX4: terça-feira | GY4: 2287.0304 | GZ4: 2380 | HA4: =GZ4/GY4 -> 1.0406508 | HC4: 2 | HD4: sexta-feira | HE4: 2824.9616 | HF4: 4655.5 | HG4: =HF4/HE4 -> 1.647987 | HI4: 2 | HJ4: segunda-feira | HK4: 2688.7593 | HL4: 2024.5 | HM4: =HL4/HK4 -> 0.75294952 | HO4: 2 | HP4: segunda-feira | HQ4: 2600.9631 | HR4: 1674.5 | HS4: =HR4/HQ4 -> 0.64379998 | HU4: 2 | HV4: quinta-feira | HW4: 2871.1989 | HX4: 1926.5 | HY4: =HX4/HW4 -> 0.67097406 | IA4: 2 | IB4: sábado | IC4: 4633.3495 | ID4: 3245.5 | IE4: =ID4/IC4 -> 0.70046519
A5: 3 | B5: sexta-feira | C5: 4000 | D5: 4701.23 | E5: =D5/C5 -> 1.1753075 | G5: 3 | H5: sexta-feira | I5: 3555.4125 | J5: 3214 | K5: =J5/I5 -> 0.90397387 | M5: 3 | N5: segunda-feira | O5: 2733.978 | P5: 2511 | Q5: =P5/O5 -> 0.91844192 | S5: 3 | T5: quarta-feira | U5: 3056.8185 | V5: 2190 | W5: =V5/U5 -> 0.71643116 | Y5: 3 | Z5: sábado | AA5: 4056.9528 | AB5: 4739.5 | AC5: =AB5/AA5 -> 1.1682414 | AE5: 3 | AF5: segunda-feira | AG5: 2577.6316 | AH5: 2610.5 | AI5: =AH5/AG5 -> 1.0127514 | AK5: 3 | AL5: quinta-feira | AM5: 2961.4519 | AN5: 4248.04 | AO5: =AN5/AM5 -> 1.434445 | AQ5: 3 | AR5: domingo | AS5: 4829.4395 | AT5: 4584.01 | AU5: =AT5/AS5 -> 0.94918055 | AW5: 3 | AX5: terça-feira | AY5: 3688.7947 | AZ5: 4020 | BA5: =AZ5/AY5 -> 1.0897869 | BC5: 3 | BD5: sexta-feira | BE5: 4199.4378 | BF5: 3818.04 | BG5: =BF5/BE5 -> 0.90917883 | BI5: 3 | BJ5: domingo | BK5: 5306.6871 | BL5: 4675.5 | BM5: =BL5/BK5 -> 0.88105816 | BO5: 3 | BP5: quarta-feira | BQ5: 3756.9044 | BR5: 3345.5 | BS5: =BR5/BQ5 -> 0.89049377 | BU5: 3 | BV5: sábado | BW5: 5459.1366 | BX5: 8196.01 | BY5: =BX5/BW5 -> 1.5013382 | CA5: 3 | CB5: domingo | CC5: 6068.5452 | CD5: 7755.51 | CE5: =CD5/CC5 -> 1.277985 | CG5: 3 | CH5: quarta-feira | CI5: 4146.7939 | CJ5: 2457.5 | CK5: =CJ5/CI5 -> 0.59262651 | CM5: 3 | CN5: sexta-feira | CO5: 4759.3194 | CP5: 1931.02 | CQ5: =CP5/CO5 -> 0.40573448 | CS5: 3 | CT5: segunda-feira | CU5: 3035.46 | CV5: 2002.58 | CW5: =CV5/CU5 -> 0.65972867 | CY5: 3 | CZ5: quarta-feira | DA5: 3391.5486 | DB5: 3879.05 | DC5: =DB5/DA5 -> 1.1437401 | DE5: 3 | DF5: sábado | DG5: 4876.4236 | DH5: 2189.54 | DI5: =DH5/DG5 -> 0.4490053 | DK5: 3 | DL5: terça-feira | DM5: 3483.7085 | DN5: 2823.51 | DO5: =DN5/DM5 -> 0.81048973 | DQ5: 3 | DR5: quinta-feira | DS5: 2876.6968 | DT5: 2555.52 | DU5: =DT5/DS5 -> 0.88835222 | DW5: 3 | DX5: domingo | DY5: 4007.9167 | DZ5: 2770.5 | EA5: =DZ5/DY5 -> 0.69125688 | EC5: 3 | ED5: terça-feira | EE5: 3892.5032 | EF5: 3349.51 | EG5: =EF5/EE5 -> 0.86050282 | EI5: 3 | EJ5: sexta-feira | EK5: 3395.1738 | EL5: 2801.51 | EM5: =EL5/EK5 -> 0.8251448 | EO5: 3 | EP5: segunda-feira | EQ5: 3410.9596 | ER5: 2798.26 | ES5: =ER5/EQ5 -> 0.82037324 | EU5: 3 | EV5: segunda-feira | EW5: 3506.3663 | EX5: 4028.76 | EY5: =EX5/EW5 -> 1.1489843 | FA5: 3 | FB5: quinta-feira | FC5: 3926.0768 | FD5: 1924.01 | FE5: =FD5/FC5 -> 0.49005918 | FG5: 3 | FH5: sábado | FI5: 5462.333 | FJ5: 3847.75 | FK5: =FJ5/FI5 -> 0.70441512 | FM5: 3 | FN5: terça-feira | FO5: 3196.462 | FP5: 1909.01 | FQ5: =FP5/FO5 -> 0.59722593 | FS5: 3 | FT5: quinta-feira | FU5: 3309.5277 | FV5: 2230.26 | FW5: =FV5/FU5 -> 0.67389072 | FY5: 3 | FZ5: domingo | GA5: 4265.0085 | GB5: 3413.9 | GC5: =GB5/GA5 -> 0.80044388 | GE5: 3 | GF5: quarta-feira | GG5: 3098.3747 | GH5: 2668.51 | GI5: =GH5/GG5 -> 0.86126124 | GK5: 3 | GL5: sexta-feira | GM5: 3011.9163 | GN5: 5068.51 | GO5: =GN5/GM5 -> 1.682819 | GQ5: 3 | GR5: segunda-feira | GS5: 2925.7362 | GT5: 2232 | GU5: =GT5/GS5 -> 0.7628849 | GW5: 3 | GX5: quarta-feira | GY5: 2757.4024 | GZ5: 3015.02 | HA5: =GZ5/GY5 -> 1.0934276 | HC5: 3 | HD5: sábado | HE5: 3969.1895 | HF5: 5409.5 | HG5: =HF5/HE5 -> 1.3628727 | HI5: 3 | HJ5: terça-feira | HK5: 2784.4127 | HL5: 2597.5 | HM5: =HL5/HK5 -> 0.93287176 | HO5: 3 | HP5: terça-feira | HQ5: 2691.1035 | HR5: 3251 | HS5: =HR5/HQ5 -> 1.2080546 | HU5: 3 | HV5: sexta-feira | HW5: 2948.2952 | HX5: 2649 | HY5: =HX5/HW5 -> 0.89848534 | IA5: 3 | IB5: domingo | IC5: 4467.7141 | ID5: 6348 | IE5: =ID5/IC5 -> 1.4208608
